Workbook

Sheet Start Here
A1: Social Media Plan — Muhammad Mehrooz Shafique | Permanent SEO
A2: 6-month content calendar (Nov 2026 – Apr 2027) · LinkedIn + Instagram primary · cross-post to X, Facebook, YouTube, Reddit
A4: Brand
A5: Name on posts | B5: Muhammad Mehrooz Shafique
A6: Title | B6: SEO Expert · Co-Founder, Permanent SEO
A7: Audience | B7: E-commerce brands (Shopify, WooCommerce, online stores)
A8: Tone | B8: Confident expert. Short sentences. No fluff, no hype words, no invented stats.
A9: Brand lead | B9: Personal brand first; Permanent SEO credited on every post (logo + name tag).
A10: Call to action | B10: Every post: Comment "KEYWORD" → send that post's freebie by DM. Keyword changes per post.
A11: Colours
A12: Primary blue | B12: #1566D7 (your final brand blue — buttons, highlights, key words)
A13: Logo blue (gradient top) | B13: #345DF5
A14: Deep navy (gradient bottom / text) | B14: #191A46
A15: Mid blue | B15: #2B43B1
A16: Light background | B16: #F4F7FD
A17: White / Ink | B17: #FFFFFF / #0B0F1F
A18: Typography
A19: Headlines | B19: Bebas Neue or Anton (condensed, high impact, ALL CAPS)
A20: Body | B20: Inter (Regular/SemiBold)
A21: Photo use | B21: Small circular headshot avatar + name tag bottom-left; logo bottom-right
A22: Visual styles
A23: LinkedIn image & slides | B23: Light editorial: off-white background, navy text, blue accents, data charts, UI mockups, guide-cover layouts
A24: Instagram posts & slides | B24: Bold creator: #345DF5 → #191A46 gradient, giant white condensed headline, blue highlights
A25: Reels | B25: Monochrome studio + 3D objects + kinetic text, one blue accent, calm deep male voiceover (Solution-Wagon-style reference)
A26: Long videos | B26: Bright motion-graphics explainer with UI mockups, blue key words (BlogSEO-style reference)
A28: Plan at a glance (live counts)
A29: Metric | B29: Value
A30: Total posting days | B30: =COUNTA('Content Calendar'!B5:B134) -> 130
A31: Slide posts (Mon) | B31: =COUNTIF('Content Calendar'!H5:H134,"SLIDE") -> 26
A32: Image posts (Tue/Fri) | B32: =COUNTIF('Content Calendar'!H5:H134,"POST") -> 52
A33: Reels (Wed) | B33: =COUNTIF('Content Calendar'!H5:H134,"REEL") -> 26
A34: Long videos (Thu) | B34: =COUNTIF('Content Calendar'!H5:H134,"LONG_VIDEO") -> 26
A35: Posted so far | B35: =COUNTIF('Content Calendar'!AH5:AH134,"Posted") -> 0
A36: Scheduled | B36: =COUNTIF('Content Calendar'!AH5:AH134,"Scheduled") -> 0
A37: Progress | B37: =IFERROR(B35/B30,0) -> 0
A39: How to use
A40: 1. Open 'Content Calendar'. Each row = one posting day (Mon–Fri, 5x/week).
A41: 2. Copy 'LinkedIn Visual/Video Prompt' or 'Instagram Visual/Video Prompt' into your image/video AI tool (Canva, Higgsfield, Midjourney, Nano Banana, Kling, etc.). Upload your headshot + logo as references.
A42: 3. Copy the caption columns as-is. Hashtags are already at the end of each caption (also listed separately).
A43: 4. Cross-post using the X / Facebook / YouTube / Reddit columns on the same row.
...

Sheet Content Calendar
A1: Content Calendar — Nov 2026 to Apr 2027 (5 posts/week)
A2: Captions are ready to post. Replace [placeholders] before publishing. Times are UK time — starting points to test.
A4: # | B4: Date | C4: Day | D4: Week | E4: Month | F4: Monthly Theme | G4: Pillar | H4: Format | I4: LinkedIn Format | J4: Instagram Format | K4: Topic | L4: Hook / Cover Headline | M4: Primary Keyword | N4: Secondary Keywords | O4: LinkedIn Caption (ready) | P4: LinkedIn Hashtags | Q4: Instagram Caption (ready) | R4: Instagram Hashtags | S4: Production Brief (slides / script) | T4: LinkedIn Visual/Video Prompt (ready) | U4: Instagram Visual/Video Prompt (ready) | V4: Comment Keyword | W4: Freebie | X4: X Post / Thread | Y4: Facebook | Z4: Cross-post To | AA4: YouTube Title | AB4: YouTube Description | AC4: YouTube Tags | AD4: Reddit Subreddit | AE4: Reddit Title | AF4: Reddit Post | AG4: Post Time (LI / IG) | AH4: Status | AI4: Posted URL / Notes
A5: 1 | B5: 46328 | C5: Mon | D5: 1 | E5: Nov 2026 | F5: E-commerce SEO Foundations + Black Friday / Cyber Monday SEO | G5: Educate | H5: SLIDE | I5: LinkedIn Slide Post (PDF carousel) | J5: Instagram Slide Post (carousel) | K5: Meet Mehrooz: 8 reasons e-commerce stores lose organic traffic | L5: Your store isn't invisible by accident. Here are 8 reasons why. | M5: why is my store losing organic traffic | N5: ecommerce SEO, Shopify organic traffic drop, online store SEO problems, ecommerce traffic decline | O5: I'm Muhammad Mehrooz Shafique, Co-Founder of Permanent SEO. I work with e-commerce brands on one thing: organic traffic that stays. On this account I'll teach store owners how SEO actually works for online shops. Technical fixes. Product and category pages. Seasonal SEO. AI search. Real case breakdowns. To start, here's what I see most often when a store's organic traffic slides: → Collection pages with no unique content → Duplicate URLs from filters and variants → Seasonal pages deleted after every sale → Out-of-stock products returning 404s → Slow mobile pages loaded with apps → No internal links pointing to money pages → Product titles written for the brand, not the buyer → Nobody checking Google Search Console None of these need a bigger budget. They need someone to look. This month is all about e-commerce SEO foundations and getting ready for Black Friday and Cyber Monday. Swipe through the carousel. Then check your own store against it. Comment "LEAKS" and I'll send you the E-commerce Organic Traffic Leak Checklist. #EcommerceSEO #ShopifySEO #OrganicTraffic #PermanentSEO | P5: #EcommerceSEO #ShopifySEO #OrganicTraffic #PermanentSEO | Q5: 8 reasons your store is losing organic traffic. → Thin collection pages → Filter and variant duplicates → Deleted seasonal pages → 404s on out-of-stock products → Slow, app-heavy mobile pages I'm Mehrooz, Co-Founder of Permanent SEO. I'll be teaching e-commerce SEO here every weekday. Save this and check your store tonight. Comment "LEAKS" for the E-commerce Organic Traffic Leak Checklist. #ecommerceseo #seotips #shopifyseo #onlinestore #ecommercetips #organictraffic #smallbusinessseo #shopifystore #woocommerce #seoexpert #ecommercemarketing #storeowner | R5: #ecommerceseo #seotips #shopifyseo #onlinestore #ecommercetips #organictraffic #smallbusinessseo #shopifystore #woocommerce #seoexpert #ecommercemarketing #storeowner | S5: Slide 1: Your store isn't invisible by accident. | 8 reasons e-commerce stores lose organic traffic. Photo of Mehrooz, name + "Co-Founder, Permanent SEO" Slide 2: Who I am | Muhammad Mehrooz Shafique. I help e-commerce brands build organic traffic that stays. This account: store SEO, seasonal SEO, AI search, real breakdowns. Slide 3: Reason 1: Thin collection pages | A grid of products and no text. Google can't tell what the page is about or why it should rank. Slide 4: Reason 2: Duplicate URLs | Filters, sorting and variants create hundreds of near-identical URLs. Check canonicals. Slide 5: Reason 3: Deleted seasonal pages | Every January the Black Friday page gets deleted. Every November you start from zero. Slide 6: Reason 4: Out-of-stock 404s | Removing products kills links and rankings. Keep the page, show alternatives. Slide 7: Reason 5 + 6: Speed and internal links | Slow mobile pages lose visitors. Money pages with no internal links lose rankings. Slide 8: Reason 7 + 8: Titles and blind spots | Product titles nobody searches for. No one opening Google Search Console. Slide 9: The fix starts with a check | Not a bigger budget. A 30-minute look at the right reports. Slide 10: Comment "LEAKS" | Get the E-commerce Organic Traffic Leak Checklist. Follow Mehrooz for daily e-commerce SEO. | T5: Design a 10-slide LinkedIn PDF carousel, 1080x1350 each. Clean premium editorial style: off-white #F4F7FD background, primary blue #1566D7 accents, navy #191A46 text, headlines in Bebas Neue (bold condensed, all caps), body in Inter; generous margins, faint grid lines, crisp vector icons, no stock-photo clutter. Cover slide like a premium guide cover: giant two-tone headline (key word in blue), small illustration/UI mockup, numbered contents list. Inner slides: big slide number in blue, Bebas Neue title, short Inter body, one diagram/mockup/checklist per slide. Last slide: navy CTA banner with download icon. SLIDE CONTENT: Slide 1: Your store isn't invisible by accident. | 8 reasons e-commerce stores lose organic traffic. Photo of Mehrooz, name + "Co-Founder, Permanent SEO" Slide 2: Who I am | Muhammad Mehrooz Shafique. I help e-commerce brands build organic traffic that stays. This account: store SEO, seasonal SEO, AI search, real breakdowns. Slide 3: Reason 1: Thin collection pages | A grid of products and no text. Google can't tell what the page is about or why it should rank. Slide 4: Reason 2: Duplicate URLs | Filters, sorting and variants create hundreds of near-identical URLs. Check canonicals. Slide 5: Reason 3: Deleted seasonal pages | Every January the Black Friday page gets deleted. Every November you start from zero. Slide 6: Reason 4: Out-of-stock 404s | Removing products kills links and rankings. Keep the page, show alternatives. Slide 7: Reason 5 + 6: Speed and internal links | Slow mobile pages lose visitors. Money pages with no internal links lose rankings. Slide 8: Reason 7 + 8: Titles and blind spots | Product titles nobody searches for. No one opening Google Search Console. Slide 9: The fix starts with a check | Not a bigger budget. A 30-minute look at the right reports. Slide 10: Comment "LEAKS" | Get the E-commerce Organic Traffic Leak Checklist. Follow Mehrooz for daily e-commerce SEO. Footer on every frame: small circular headshot avatar + name tag 'Muhammad Mehrooz Shafique · Co-Founder, Permanent SEO' bottom-left; Permanent SEO 'P' logo (rising bar-chart + arrow mark) bottom-right. All text spelled exactly as written, sharp and legible on mobile; no extra words, no watermarks. | U5: Design a 10-slide Instagram carousel, 1080x1350 each. Bold creator style: deep gradient background #345DF5 (top) to #191A46 (bottom), huge white Bebas Neue / Anton condensed headline, key words highlighted in #1566D7 highlight boxes or light-blue text, high contrast. Slide 1 = scroll-stopping cover with giant condensed headline and a 'swipe →' cue; inner slides alternate navy and white backgrounds, big blue slide number, max 25 words, one icon or mini-diagram each; last slide = CTA with comment keyword in a blue pill. SLIDE CONTENT: Slide 1: Your store isn't invisible by accident. | 8 reasons e-commerce stores lose organic traffic. Photo of Mehrooz, name + "Co-Founder, Permanent SEO" Slide 2: Who I am | Muhammad Mehrooz Shafique. I help e-commerce brands build organic traffic that stays. This account: store SEO, seasonal SEO, AI search, real breakdowns. Slide 3: Reason 1: Thin collection pages | A grid of products and no text. Google can't tell what the page is about or why it should rank. Slide 4: Reason 2: Duplicate URLs | Filters, sorting and variants create hundreds of near-identical URLs. Check canonicals. Slide 5: Reason 3: Deleted seasonal pages | Every January the Black Friday page gets deleted. Every November you start from zero. Slide 6: Reason 4: Out-of-stock 404s | Removing products kills links and rankings. Keep the page, show alternatives. Slide 7: Reason 5 + 6: Speed and internal links | Slow mobile pages lose visitors. Money pages with no internal links lose rankings. Slide 8: Reason 7 + 8: Titles and blind spots | Product titles nobody searches for. No one opening Google Search Console. Slide 9: The fix starts with a check | Not a bigger budget. A 30-minute look at the right reports. Slide 10: Comment "LEAKS" | Get the E-commerce Organic Traffic Leak Checklist. Follow Mehrooz for daily e-commerce SEO. Footer on every frame: small circular headshot avatar + name tag 'Muhammad Mehrooz Shafique · Co-Founder, Permanent SEO' bottom-left; Permanent SEO 'P' logo (rising bar-chart + arrow mark) bottom-right. All text spelled exactly as written, sharp and legible on mobile; no extra words, no watermarks. | V5: LEAKS | W5: E-commerce Organic Traffic Leak Checklist (PDF, 8 checks) | X5: I'm Mehrooz, Co-Founder of Permanent SEO. I help e-commerce stores get organic traffic that stays. First thread: 8 reasons stores lose organic traffic. --- 1. Thin collection pages. A product grid with no text gives Google nothing to rank. 2. Duplicate URLs. Filters, sorting and variants create near-identical pages. Check your canonicals. --- 3. Deleted seasonal pages. Delete the Black Friday page in January and you start from zero every November. 4. Out-of-stock 404s. Keep the URL. Show alternatives. --- 5. Slow mobile pages. Every app adds weight. 6. No internal links to money pages. If you don't link to it, Google treats it as less important. --- 7. Product titles nobody searches for. 8. Nobody opening Google Search Console. None of this needs more budget. It needs a check. #EcommerceSEO | Y5: Repost the Instagram caption + same visual | Z5: X thread · Facebook carousel · Reddit text post | AD5: r/ecommerce | AE5: The 8 most common reasons I see e-commerce stores lose organic traffic | AF5: I audit online stores for a living, mostly Shopify and WooCommerce. The same issues show up again and again when organic traffic slides, so here's the list. 1. Collection pages with zero unique text. Just a product grid. 2. Duplicate URLs from filters, sort parameters and variants, with weak or missing canonicals. 3. Seasonal pages (Black Friday, Christmas) deleted after the sale, so every year starts with no history. 4. Out-of-stock products removed and left as 404s, losing their links. 5. Slow mobile pages, usually from too many apps and scripts. 6. Important category pages with almost no internal links. 7. Product titles written in brand language instead of the words buyers search. 8. Nobody checking Google Search Console, so drops go unnoticed for months. Most of these are fixable in an afternoon once you know where to look. Search Console's Pages report and Performance report catch most of them. Which of these have you run into on your own store, and did fixing it change anything? | AG5: 08:30 / 12:30 | AH5: Planned
A6: 2 | B6: 46329 | C6: Tue | D6: 1 | E6: Nov 2026 | F6: E-commerce SEO Foundations + Black Friday / Cyber Monday SEO | G6: Data & Insight | H6: POST | I6: LinkedIn Post (detailed image) | J6: Instagram Post (single image) | K6: The 10-point store SEO audit you can run in one hour | L6: The 10-point store SEO audit. One hour. No tools you don't have. | M6: ecommerce SEO audit checklist | N6: Shopify SEO audit, online store SEO audit, ecommerce technical SEO, store SEO checklist | O6: Most store owners think an SEO audit needs expensive software. It doesn't. The basics need Google Search Console, a browser and one hour. Here's the 10-point check I start every store audit with: 1. Pages report: how many URLs are indexed vs not indexed 2. Top 20 queries: are they buying queries or random ones 3. Homepage title tag: does it say what you sell 4. Collection pages: is there unique text above or below the grid 5. Product titles: do they match how buyers search 6. Canonicals on filtered URLs 7. Out-of-stock products: live page or 404 8. Core Web Vitals report on mobile 9. Internal links to your top 5 collections 10. Last year's seasonal URLs: still live or deleted If you find problems in 3 or more, your store is leaving organic revenue on the table. The image breaks down where to find each one. Comment "STORECHECK" and I'll send you the 10-Point Store SEO Audit Sheet. #EcommerceSEO #SEOAudit #ShopifySEO #GoogleSearchConsole | P6: #EcommerceSEO #SEOAudit #ShopifySEO #GoogleSearchConsole | Q6: The 10-point store SEO audit. → Indexed vs not indexed pages → Top 20 queries: buying or random? → Unique text on collection pages → Canonicals on filter URLs → Out-of-stock pages: live or 404? One hour. Search Console and a browser. Fix the cheapest problems first. Save this for your next quiet afternoon. Comment "STORECHECK" for the 10-Point Store SEO Audit Sheet. #seoaudit #ecommerceseo #shopifyseo #seotips #onlinestore #woocommerce #googlesearchconsole #ecommercetips #technicalseo #storeowner #shopifytips #digitalmarketing | R6: #seoaudit #ecommerceseo #shopifyseo #seotips #onlinestore #woocommerce #googlesearchconsole #ecommercetips #technicalseo #storeowner #shopifytips #digitalmarketing | S6: Single image, 1080x1350 (IG) and 1200x1500 (LinkedIn). Style: clean checklist infographic, dark navy background, white text, one accent colour (green ticks). Headline (top, bold condensed): THE 10-POINT STORE SEO AUDIT Sub-headline: One hour. Google Search Console + a browser. Numbered list in two columns, each item = check + where to find it: 1. Indexed vs not indexed | GSC > Pages 2. Top 20 queries | GSC > Performance > Queries 3. Homepage title tag | View source / browser tab 4. Collection page text | Your top 5 collections 5. Product titles vs searches | GSC queries vs product names 6. Canonicals on filter URLs | View source on a filtered URL 7. Out-of-stock handling | Visit 3 sold-out products 8. Mobile Core Web Vitals | GSC > Core Web Vitals 9. Internal links to top collections | Homepage + menu + blog 10. Last year's seasonal URLs | Type /black-friday into your domain Bottom bar: "3+ problems = organic revenue left on the table" | Footer: Mehrooz Shafique · Permanent SEO | Banner: Comment "STORECHECK" for the audit sheet | T6: Create a 1080x1350 LinkedIn infographic. Clean premium editorial style: off-white #F4F7FD background, primary blue #1566D7 accents, navy #191A46 text, headlines in Bebas Neue (bold condensed, all caps), body in Inter; generous margins, faint grid lines, crisp vector icons, no stock-photo clutter. HEADLINE: "The 10-point store SEO audit. One hour. No tools you don't have." SUBHEAD: "The 10-point store SEO audit you can run in one hour" MAIN VISUAL: the layout described below containing exactly: Single image, 1080x1350 (IG) and 1200x1500 (LinkedIn). Style: clean checklist infographic, dark navy background, white text, one accent colour (green ticks). Headline (top, bold condensed): THE 10-POINT STORE SEO AUDIT Sub-headline: One hour. Google Search Console + a browser. Numbered list in two columns, each item = check + where to find it: 1. Indexed vs not indexed | GSC > Pages 2. Top 20 queries | GSC > Performance > Queries 3. Homepage title tag | View source / browser tab 4. Collection page text | Your top 5 collections 5. Product titles vs searches | GSC queries vs product names 6. Canonicals on filter URLs | View source on a filtered URL 7. Out-of-stock handling | Visit 3 sold-out products 8. Mobile Core Web Vitals | GSC > Core Web Vitals 9. Internal links to top collections | Homepage + menu + blog 10. Last year's seasonal URLs | Type /black-friday into your domain Bottom bar: "3+ problems = organic revenue left on the table" | Footer: Mehrooz Shafique · Permanent SEO | Banner: Comment "STORECHECK" for the audit sheet CTA BANNER (bottom, navy rounded box, white text, keyword in blue): Comment "STORECHECK" for 10-Point Store SEO Audit Sheet (Google Sheet with where-to-check notes) Footer on every frame: small circular headshot avatar + name tag 'Muhammad Mehrooz Shafique · Co-Founder, Permanent SEO' bottom-left; Permanent SEO 'P' logo (rising bar-chart + arrow mark) bottom-right. All text spelled exactly as written, sharp and legible on mobile; no extra words, no watermarks. | U6: Create a 1080x1350 Instagram post. Bold creator style: deep gradient background #345DF5 (top) to #191A46 (bottom), huge white Bebas Neue / Anton condensed headline, key words highlighted in #1566D7 highlight boxes or light-blue text, high contrast. HEADLINE (top, 2–3 lines, giant): "The 10-point store SEO audit. One hour. No tools you don't have." BODY (numbered points / simple visual): the 3–5 key points from this brief, shortened to max 8 words each: Single image, 1080x1350 (IG) and 1200x1500 (LinkedIn). Style: clean checklist infographic, dark navy background, white text, one accent colour (green ticks). Headline (top, bold condensed): THE 10-POINT STORE SEO AUDIT Sub-headline: One hour. Google Search Console + a browser. Numbered list in two columns, each item = check + where to find it: 1. Indexed vs not indexed | GSC > Pages 2. Top 20 queries | GSC > Performance > Queries 3. Homepage title tag | View source / browser tab 4. Collection page text | Your top 5 collections 5. Product titles vs searches | GSC queries vs product names 6. Canonicals on filter URLs | View source on a filtered URL 7. Out-of-stock handling | Visit 3 sold-out products 8. Mobile Core Web Vitals | GSC > Core Web Vitals 9. Internal links to top collections | Homepage + menu + blog 10. Last year's seasonal URLs | Type /black-friday into your domain Bottom bar: "3+ problems = organic revenue left on the table" | Footer: Mehrooz Shafique · Permanent SEO | Banner: Comment "STORECHECK" for the audit sheet BOTTOM BAR: Comment "STORECHECK" for 10-Point Store SEO Audit Sheet (Google Sheet with where-to-check notes) Footer on every frame: small circular headshot avatar + name tag 'Muhammad Mehrooz Shafique · Co-Founder, Permanent SEO' bottom-left; Permanent SEO 'P' logo (rising bar-chart + arrow mark) bottom-right (white versions). All text spelled exactly as written, sharp and legible on mobile; no extra words, no watermarks. | V6: STORECHECK | W6: 10-Point Store SEO Audit Sheet (Google Sheet with where-to-check notes) | X6: A store SEO audit doesn't need paid tools. Search Console + a browser + 1 hour: → Indexed vs not indexed → Top 20 queries → Collection page text → Filter canonicals → Out-of-stock pages → Mobile CWV → Last year's BFCM URLs #EcommerceSEO | Y6: Repost the Instagram caption + same visual | Z6: X post + image · Facebook image post | AG6: 08:30 / 18:30 | AH6: Planned
A7: 3 | B7: 46330 | C7: Wed | D7: 1 | E7: Nov 2026 | F7: E-commerce SEO Foundations + Black Friday / Cyber Monday SEO | G7: Myth-Busting | H7: REEL | I7: LinkedIn native vertical video | J7: Instagram Reel (9:16) | K7: Myth: delete your Black Friday page after the sale | L7: We don't delete Black Friday pages. We keep them. | M7: black friday landing page SEO | N7: evergreen black friday URL, seasonal landing page SEO, BFCM page SEO, should I delete black friday page | O7: Most stores delete their Black Friday page in December. Then rebuild it from scratch every November. That's the mistake, and it costs more every year. A page that has existed for years has history. Links from deal sites. Mentions. Clicks. Google has seen it before. A new URL every year starts at zero. Two weeks before the biggest sales weekend. What to do instead: → One permanent URL: /black-friday (no year in it) → After the sale, update the page: "Our next Black Friday sale is coming. Join the list." → Keep it in your footer or sitemap so it stays indexed → Refresh the content each October The page sleeps. The authority doesn't. Comment "EVERGREEN" and I'll send you the Evergreen Seasonal Page Template. #BlackFriday #EcommerceSEO #ShopifySEO #SeasonalSEO | P7: #BlackFriday #EcommerceSEO #ShopifySEO #SeasonalSEO | Q7: Don't delete your Black Friday page. → Keep one URL with no year in it → After the sale, switch it to "coming soon + join the list" → Keep it indexed → Refresh it every October The page sleeps. The authority doesn't. Share this with a store owner who rebuilds every year. Comment "EVERGREEN" for the Evergreen Seasonal Page Template. #blackfriday #blackfridaysale #ecommerceseo #shopifyseo #seotips #onlinestore #ecommercetips #cybermonday #shopifystore #smallbusiness #seasonalmarketing #woocommerce | R7: #blackfriday #blackfridaysale #ecommerceseo #shopifyseo #seotips #onlinestore #ecommercetips #cybermonday #shopifystore #smallbusiness #seasonalmarketing #woocommerce | S7: [0-2s] VO: We don't delete Black Friday pages. | ON-SCREEN: WE DON'T DELETE BLACK FRIDAY PAGES. | VISUAL: Bold white kinetic type on black, a page icon being dragged to a bin then stopped [2-4s] VO: We keep them. | ON-SCREEN: WE KEEP THEM. | VISUAL: Page icon snaps back, glows [4-7s] VO: Most stores do the same thing every December. | ON-SCREEN: MOST STORES, EVERY DECEMBER: | VISUAL: Calendar flips to December [7-9s] VO: Sale ends. | ON-SCREEN: SALE ENDS. | VISUAL: Price tag fades [9-10s] VO: Page deleted. | ON-SCREEN: PAGE DELETED. | VISUAL: 404 flashes [10-12s] VO: Rebuilt in November. | ON-SCREEN: REBUILT IN NOVEMBER. | VISUAL: Empty page skeleton [12-15s] VO: But a seasonal page needs three things. | ON-SCREEN: BUT IT NEEDS 3 THINGS | VISUAL: Three empty slots [15-18s] VO: One URL. No year in it. | ON-SCREEN: 1. ONE URL. NO YEAR. | VISUAL: /black-friday typed in a browser bar [18-21s] VO: A holding message after the sale. | ON-SCREEN: 2. A HOLDING MESSAGE | VISUAL: "Next sale coming. Join the list." [21-24s] VO: A refresh every October. | ON-SCREEN: 3. A REFRESH EVERY OCTOBER | VISUAL: Calendar to October, page updates [24-27s] VO: Without those three, every single year starts at zero. | ON-SCREEN: EVERY YEAR STARTS AT ZERO | VISUAL: Counter resets to 0 [27-29s] VO: The page sleeps. | ON-SCREEN: THE PAGE SLEEPS. | VISUAL: Page dims [29-32s] VO: The authority doesn't. | ON-SCREEN: THE AUTHORITY DOESN'T. | VISUAL: Page pulses; end card "Comment EVERGREEN" + @Mehrooz · Permanent SEO | T7: Same video as Instagram Reel (upload natively, 9:16, add captions). See Instagram prompt → | U7: Produce a 1080x1920 vertical reel, 25–35 s. Visual style: soft white studio background with subtle grid and soft corner shadows, mostly monochrome (black, grey, white) with ONE accent colour blue #1566D7; cinematic 3D objects (rocket, credit card, balance scale, puzzle pieces, magnifying glass, Google/Shopify-style app icons) that move in with motion blur; kinetic typography: bold geometric sans, one or two words per beat, key word in large grey/blue. Permanent SEO logo small at top-centre throughout. Voiceover: calm, deep, confident male narrator; measured pace (~130 words/min); a short pause between every line; no hype, no music drops over the voice; subtle minimal ambient bed + soft whoosh on text changes. BEATS: [0-2s] VO: We don't delete Black Friday pages. | ON-SCREEN: WE DON'T DELETE BLACK FRIDAY PAGES. | VISUAL: Bold white kinetic type on black, a page icon being dragged to a bin then stopped [2-4s] VO: We keep them. | ON-SCREEN: WE KEEP THEM. | VISUAL: Page icon snaps back, glows [4-7s] VO: Most stores do the same thing every December. | ON-SCREEN: MOST STORES, EVERY DECEMBER: | VISUAL: Calendar flips to December [7-9s] VO: Sale ends. | ON-SCREEN: SALE ENDS. | VISUAL: Price tag fades [9-10s] VO: Page deleted. | ON-SCREEN: PAGE DELETED. | VISUAL: 404 flashes [10-12s] VO: Rebuilt in November. | ON-SCREEN: REBUILT IN NOVEMBER. | VISUAL: Empty page skeleton [12-15s] VO: But a seasonal page needs three things. | ON-SCREEN: BUT IT NEEDS 3 THINGS | VISUAL: Three empty slots [15-18s] VO: One URL. No year in it. | ON-SCREEN: 1. ONE URL. NO YEAR. | VISUAL: /black-friday typed in a browser bar [18-21s] VO: A holding message after the sale. | ON-SCREEN: 2. A HOLDING MESSAGE | VISUAL: "Next sale coming. Join the list." [21-24s] VO: A refresh every October. | ON-SCREEN: 3. A REFRESH EVERY OCTOBER | VISUAL: Calendar to October, page updates [24-27s] VO: Without those three, every single year starts at zero. | ON-SCREEN: EVERY YEAR STARTS AT ZERO | VISUAL: Counter resets to 0 [27-29s] VO: The page sleeps. | ON-SCREEN: THE PAGE SLEEPS. | VISUAL: Page dims [29-32s] VO: The authority doesn't. | ON-SCREEN: THE AUTHORITY DOESN'T. | VISUAL: Page pulses; end card "Comment EVERGREEN" + @Mehrooz · Permanent SEO Final 3 s: dark/navy end card with Permanent SEO logo, 'SEO for E-commerce Brands' and 'Comment "EVERGREEN"'. Burned-in captions. All text spelled exactly as written, sharp and legible on mobile; no extra words, no watermarks. | V7: EVERGREEN | W7: Evergreen Seasonal Page Template (Black Friday / Cyber Monday page outline + off-season copy) | X7: Stop deleting your Black Friday page in December. One URL. No year in it. Holding message after the sale. Refresh in October. A new URL every year starts at zero. The page sleeps. The authority doesn't. #BlackFriday #EcommerceSEO | Y7: Repost the Instagram caption + same visual as Facebook Reel | Z7: YouTube Shorts · Facebook Reels · X video | AA7: Black Friday Landing Page SEO: Why You Should Never Delete It | AB7: Black Friday landing page SEO in 30 seconds: keep one permanent URL, switch it to a holding message after the sale, and refresh it every October so it keeps its authority. #Shorts | AC7: black friday landing page SEO, black friday SEO, seasonal landing page, ecommerce SEO, shopify SEO, BFCM SEO, evergreen URL, cyber monday SEO, online store SEO, Permanent SEO | AG7: 12:00 / 19:00 | AH7: Planned
A8: 4 | B8: 46331 | C8: Thu | D8: 1 | E8: Nov 2026 | F8: E-commerce SEO Foundations + Black Friday / Cyber Monday SEO | G8: Explainer | H8: LONG_VIDEO | I8: LinkedIn Long Video (16:9) | J8: Instagram Reel (30–45 s vertical cut) | K8: Google Search Console for store owners: the 4 reports that matter | L8: You don't need all of Search Console. You need 4 reports. | M8: google search console for ecommerce | N8: Search Console for Shopify, GSC performance report, GSC pages report, Search Console tutorial for store owners | O8: Most store owners open Google Search Console once, see 40 menus, and close it. You don't need all of it. You need 4 reports. 1. Performance → Queries What people actually type before they find you. Sort by impressions. Look for buying queries with low clicks. 2. Performance → Pages Which product and collection pages earn clicks. Compare this month vs last year to see seasonal patterns. 3. Pages (Indexing) Which URLs Google refuses to index, and why. "Crawled, currently not indexed" on a collection page is a warning sign. 4. Core Web Vitals Mobile first. Poor URLs here will hurt you most when traffic peaks. 15 minutes a week across these 4 reports will tell you more about your store than most monthly reports. The video walks through each one. Comment "CONSOLE" and I'll send you the Search Console Weekly Routine for Store Owners. #GoogleSearchConsole #EcommerceSEO #ShopifySEO #SEO | P8: #GoogleSearchConsole #EcommerceSEO #ShopifySEO #SEO | Q8: Search Console has 40 menus. Store owners need 4. → Performance: Queries → Performance: Pages → Pages (Indexing) → Core Web Vitals 15 minutes a week. That's it. Start with queries that get impressions but no clicks. Those are usually the quickest wins. Save this before your next login. Comment "CONSOLE" for the Search Console Weekly Routine for Store Owners. #googlesearchconsole #ecommerceseo #seotips #shopifyseo #onlinestore #storeowner #seoforbeginners #woocommerce #ecommercetips #shopifytips #technicalseo #digitalmarketing | R8: #googlesearchconsole #ecommerceseo #seotips #shopifyseo #onlinestore #storeowner #seoforbeginners #woocommerce #ecommercetips #shopifytips #technicalseo #digitalmarketing | S8: Scene 1 [0-10s] VO: "Okay. Search Console. Performance, Pages, Links, Experience, Enhancements... yeah, I'll look at this later." Close tab. | VISUAL: Animated store owner at laptop, GSC sidebar menus multiplying, tab closes Scene 2 [10-20s] VO: "Let's be honest. The data on why your store isn't growing is already in there. You just don't know which part to read." | VISUAL: Magnifier over a blurred dashboard Scene 3 [20-30s] VO: "So you guess. More products. More ads. More blog posts. And the real problems sit there untouched." | VISUAL: Three icons stacking, a red warning blinking underneath Scene 4 [30-38s] VO: "Here's how we use it at Permanent SEO. Four reports. Fifteen minutes a week." | VISUAL: Logo, then four tiles Scene 5 [38-50s] VO: "One. Performance, queries. Sort by impressions. Find buying searches where you show up but nobody clicks. Those titles need work." | VISUAL: Query table, high-impression low-CTR rows highlighted Scene 6 [50-62s] VO: "Two. Performance, pages. See which collections and products earn clicks. Compare to last year to spot seasonal pages." | VISUAL: Date compare toggle, line chart rising in November Scene 7 [62-74s] VO: "Three. The Pages report. If a collection says crawled, currently not indexed, Google doesn't think it's worth showing." | VISUAL: Indexing reasons list, collection URL flagged Scene 8 [74-84s] VO: "Four. Core Web Vitals, on mobile. Fix poor URLs before peak traffic, not during it." | VISUAL: Poor / needs improvement / good bars Scene 9 [84-92s] VO: "That's the result we look for: [CLIENT RESULT: what changed after weekly GSC reviews]." | VISUAL: Placeholder results card Scene 10 [92-105s] VO: "Comment CONSOLE and I'll send you the weekly routine. Or book a free e-commerce SEO audit with Permanent SEO." | VISUAL: End card, keyword, Mehrooz name + Permanent SEO | T8: Produce a 1920x1080 motion-graphics explainer, 60–120 s. Visual style: bright white/very light blue #F4F7FD canvas, floating UI mockups (Google results, Search Console charts, product pages, ChatGPT answers), kinetic typography where key words turn blue #1566D7, smooth parallax and soft shadows, occasional full-bleed blue #1566D7 scene with one giant word. Voiceover: calm, deep, confident male narrator; measured pace (~130 words/min); a short pause between every line; no hype, no music drops over the voice; subtle minimal ambient bed + soft whoosh on text changes. SCRIPT & SCENES: Scene 1 [0-10s] VO: "Okay. Search Console. Performance, Pages, Links, Experience, Enhancements... yeah, I'll look at this later." Close tab. | VISUAL: Animated store owner at laptop, GSC sidebar menus multiplying, tab closes Scene 2 [10-20s] VO: "Let's be honest. The data on why your store isn't growing is already in there. You just don't know which part to read." | VISUAL: Magnifier over a blurred dashboard Scene 3 [20-30s] VO: "So you guess. More products. More ads. More blog posts. And the real problems sit there untouched." | VISUAL: Three icons stacking, a red warning blinking underneath Scene 4 [30-38s] VO: "Here's how we use it at Permanent SEO. Four reports. Fifteen minutes a week." | VISUAL: Logo, then four tiles Scene 5 [38-50s] VO: "One. Performance, queries. Sort by impressions. Find buying searches where you show up but nobody clicks. Those titles need work." | VISUAL: Query table, high-impression low-CTR rows highlighted Scene 6 [50-62s] VO: "Two. Performance, pages. See which collections and products earn clicks. Compare to last year to spot seasonal pages." | VISUAL: Date compare toggle, line chart rising in November Scene 7 [62-74s] VO: "Three. The Pages report. If a collection says crawled, currently not indexed, Google doesn't think it's worth showing." | VISUAL: Indexing reasons list, collection URL flagged Scene 8 [74-84s] VO: "Four. Core Web Vitals, on mobile. Fix poor URLs before peak traffic, not during it." | VISUAL: Poor / needs improvement / good bars Scene 9 [84-92s] VO: "That's the result we look for: [CLIENT RESULT: what changed after weekly GSC reviews]." | VISUAL: Placeholder results card Scene 10 [92-105s] VO: "Comment CONSOLE and I'll send you the weekly routine. Or book a free e-commerce SEO audit with Permanent SEO." | VISUAL: End card, keyword, Mehrooz name + Permanent SEO End card: Permanent SEO logo + 'Comment "CONSOLE"' + 'Muhammad Mehrooz Shafique · Co-Founder, Permanent SEO'. Burn in captions. All text spelled exactly as written, sharp and legible on mobile; no extra words, no watermarks. | U8: Produce a 1080x1920 vertical reel, 25–35 s. Visual style: soft white studio background with subtle grid and soft corner shadows, mostly monochrome (black, grey, white) with ONE accent colour blue #1566D7; cinematic 3D objects (rocket, credit card, balance scale, puzzle pieces, magnifying glass, Google/Shopify-style app icons) that move in with motion blur; kinetic typography: bold geometric sans, one or two words per beat, key word in large grey/blue. Permanent SEO logo small at top-centre throughout. Voiceover: calm, deep, confident male narrator; measured pace (~130 words/min); a short pause between every line; no hype, no music drops over the voice; subtle minimal ambient bed + soft whoosh on text changes. BEATS: Vertical 30–45 s cut of the long video: keep the opener, the problem line, the 3–4 steps as one-word beats and the CTA. Source script: Scene 1 [0-10s] VO: "Okay. Search Console. Performance, Pages, Links, Experience, Enhancements... yeah, I'll look at this later." Close tab. | VISUAL: Animated store owner at laptop, GSC sidebar menus multiplying, tab closes Scene 2 [10-20s] VO: "Let's be honest. The data on why your store isn't growing is already in there. You just don't know which part to read." | VISUAL: Magnifier over a blurred dashboard Scene 3 [20-30s] VO: "So you guess. More products. More ads. More blog posts. And the real problems sit there untouched." | VISUAL: Three icons stacking, a red warning blinking underneath Scene 4 [30-38s] VO: "Here's how we use it at Permanent SEO. Four reports. Fifteen minutes a week." | VISUAL: Logo, then four tiles Scene 5 [38-50s] VO: "One. Performance, queries. Sort by impressions. Find buying searches where you show up but nobody clicks. Those titles need work." | VISUAL: Query table, high-impression low-CTR rows highlighted Scene 6 [50-62s] VO: "Two. Performance, pages. See which collections and products earn clicks. Compare to last year to spot seasonal pages." | VISUAL: Date compare toggle, line chart rising in November Scene 7 [62-74s] VO: "Three. The Pages report. If a collection says crawled, currently not indexed, Google doesn't think it's worth showing." | VISUAL: Indexing reasons list, collection URL flagged Scene 8 [74-84s] VO: "Four. Core Web Vitals, on mobile. Fix poor URLs before peak traffic, not during it." | VISUAL: Poor / needs improvement / good bars Scene 9 [84-92s] VO: "That's the result we look for: [CLIENT RESULT: what changed after weekly GSC reviews]." | VISUAL: Placeholder results card Scene 10 [92-105s] VO: "Comment CONSOLE and I'll send you the weekly routine. Or book a free e-commerce SEO audit with Permanent SEO." | VISUAL: End card, keyword, Mehrooz name + Permanent SEO Final 3 s: dark/navy end card with Permanent SEO logo, 'SEO for E-commerce Brands' and 'Comment "CONSOLE"'. Burned-in captions. All text spelled exactly as written, sharp and legible on mobile; no extra words, no watermarks. | V8: CONSOLE | W8: Search Console Weekly Routine for Store Owners (15-minute checklist PDF) | X8: Store owners don't need all of Google Search Console. Just 4 reports: 1. Performance → Queries 2. Performance → Pages 3. Pages (Indexing) 4. Core Web Vitals (mobile) 15 minutes a week. #EcommerceSEO | Y8: Repost the Instagram caption + same visual (upload 16:9 natively) | Z8: YouTube long video · Facebook native video · X clip (first 45 s) | AA8: Google Search Console for Ecommerce: The Only 4 Reports You Need | AB8: Google Search Console for ecommerce explained for store owners. Mehrooz Shafique from Permanent SEO walks through the 4 reports that show why your store isn't growing, and a 15-minute weekly routine to use them. | AC8: google search console for ecommerce, search console tutorial, shopify SEO, ecommerce SEO, GSC performance report, GSC pages report, core web vitals, store owner SEO, woocommerce SEO, Permanent SEO | AG8: 08:30 / 18:30 | AH8: Planned
A9: 5 | B9: 46332 | C9: Fri | D9: 1 | E9: Nov 2026 | F9: E-commerce SEO Foundations + Black Friday / Cyber Monday SEO | G9: Proof & Freebie | H9: POST | I9: LinkedIn Post (detailed image) | J9: Instagram Post (single image) | K9: Free guide preview: the Black Friday SEO Playbook for stores | L9: The Black Friday SEO Playbook. 7 chapters. Free. | M9: black friday SEO checklist | N9: BFCM SEO, Black Friday SEO tips, cyber monday SEO, holiday ecommerce SEO | O9: Black Friday is 27 November. Cyber Monday is 30 November. Three weeks is enough time to fix the SEO basics. It's not enough to start from nothing. So I put everything we check before peak season into one playbook: 1. The permanent BFCM URL strategy 2. Search Console checks for the next 21 days 3. Category vs product page intent for deal searches 4. Internal linking to holiday collections 5. Merchant Center free listings setup 6. Out-of-stock rules for sale week 7. Speed fixes before traffic peaks No theory. Each chapter ends with a short checklist you can hand to whoever runs your store. I'm giving it away free this month. Comment "PLAYBOOK" and I'll send you the Black Friday SEO Playbook. #BlackFriday #CyberMonday #EcommerceSEO #ShopifySEO | P9: #BlackFriday #CyberMonday #EcommerceSEO #ShopifySEO | Q9: The Black Friday SEO Playbook. Free. 1. Permanent BFCM URLs 2. Search Console checks 3. Category vs product intent 4. Internal links to holiday collections 5. Merchant Center free listings 6. Out-of-stock rules 7. Speed before peak Each chapter ends with a short checklist you can hand to your team. Three weeks left. Save this. Comment "PLAYBOOK" for the Black Friday SEO Playbook. #blackfriday #cybermonday #bfcm #ecommerceseo #shopifyseo #seotips #onlinestore #blackfridaysale #ecommercetips #shopifystore #woocommerce #holidaymarketing #smallbusiness | R9: #blackfriday #cybermonday #bfcm #ecommerceseo #shopifyseo #seotips #onlinestore #blackfridaysale #ecommercetips #shopifystore #woocommerce #holidaymarketing #smallbusiness | S9: Single image "guide preview", 1080x1350. Layout: left 55% = mock 3D cover of an ebook titled "THE BLACK FRIDAY SEO PLAYBOOK" with sub-title "For Shopify & WooCommerce stores · 2026 edition" and author line "Muhammad Mehrooz Shafique · Permanent SEO". Right 45% = "INSIDE:" with numbered chapters: 01 The permanent BFCM URL strategy 02 Search Console: 21-day checks 03 Category vs product intent 04 Internal links to holiday collections 05 Merchant Center free listings 06 Out-of-stock rules for sale week 07 Speed fixes before peak traffic Top corner tag: "Black Friday 27 Nov · Cyber Monday 30 Nov". Bottom full-width banner, bright accent colour: Comment "PLAYBOOK" for free access. | T9: Create a 1080x1350 LinkedIn infographic. Clean premium editorial style: off-white #F4F7FD background, primary blue #1566D7 accents, navy #191A46 text, headlines in Bebas Neue (bold condensed, all caps), body in Inter; generous margins, faint grid lines, crisp vector icons, no stock-photo clutter. HEADLINE: "The Black Friday SEO Playbook. 7 chapters. Free." SUBHEAD: "Free guide preview: the Black Friday SEO Playbook for stores" MAIN VISUAL: the layout described below containing exactly: Single image "guide preview", 1080x1350. Layout: left 55% = mock 3D cover of an ebook titled "THE BLACK FRIDAY SEO PLAYBOOK" with sub-title "For Shopify & WooCommerce stores · 2026 edition" and author line "Muhammad Mehrooz Shafique · Permanent SEO". Right 45% = "INSIDE:" with numbered chapters: 01 The permanent BFCM URL strategy 02 Search Console: 21-day checks 03 Category vs product intent 04 Internal links to holiday collections 05 Merchant Center free listings 06 Out-of-stock rules for sale week 07 Speed fixes before peak traffic Top corner tag: "Black Friday 27 Nov · Cyber Monday 30 Nov". Bottom full-width banner, bright accent colour: Comment "PLAYBOOK" for free access. CTA BANNER (bottom, navy rounded box, white text, keyword in blue): Comment "PLAYBOOK" for Black Friday SEO Playbook (7-chapter PDF with checklists) Footer on every frame: small circular headshot avatar + name tag 'Muhammad Mehrooz Shafique · Co-Founder, Permanent SEO' bottom-left; Permanent SEO 'P' logo (rising bar-chart + arrow mark) bottom-right. All text spelled exactly as written, sharp and legible on mobile; no extra words, no watermarks. | U9: Create a 1080x1350 Instagram post. Bold creator style: deep gradient background #345DF5 (top) to #191A46 (bottom), huge white Bebas Neue / Anton condensed headline, key words highlighted in #1566D7 highlight boxes or light-blue text, high contrast. HEADLINE (top, 2–3 lines, giant): "The Black Friday SEO Playbook. 7 chapters. Free." BODY (numbered points / simple visual): the 3–5 key points from this brief, shortened to max 8 words each: Single image "guide preview", 1080x1350. Layout: left 55% = mock 3D cover of an ebook titled "THE BLACK FRIDAY SEO PLAYBOOK" with sub-title "For Shopify & WooCommerce stores · 2026 edition" and author line "Muhammad Mehrooz Shafique · Permanent SEO". Right 45% = "INSIDE:" with numbered chapters: 01 The permanent BFCM URL strategy 02 Search Console: 21-day checks 03 Category vs product intent 04 Internal links to holiday collections 05 Merchant Center free listings 06 Out-of-stock rules for sale week 07 Speed fixes before peak traffic Top corner tag: "Black Friday 27 Nov · Cyber Monday 30 Nov". Bottom full-width banner, bright accent colour: Comment "PLAYBOOK" for free access. BOTTOM BAR: Comment "PLAYBOOK" for Black Friday SEO Playbook (7-chapter PDF with checklists) Footer on every frame: small circular headshot avatar + name tag 'Muhammad Mehrooz Shafique · Co-Founder, Permanent SEO' bottom-left; Permanent SEO 'P' logo (rising bar-chart + arrow mark) bottom-right (white versions). All text spelled exactly as written, sharp and legible on mobile; no extra words, no watermarks. | V9: PLAYBOOK | W9: Black Friday SEO Playbook (7-chapter PDF with checklists) | X9: Black Friday is 27 Nov. Three weeks left. I wrote a free Black Friday SEO Playbook: permanent URLs, GSC checks, intent, internal links, Merchant Center, out-of-stock rules, speed. Reply "PLAYBOOK" and I'll send it. #BlackFriday #EcommerceSEO | Y9: Repost the Instagram caption + same visual | Z9: X post + image · Facebook image post | AG9: 09:00 / 12:30 | AH9: Planned
A10: 6 | B10: 46335 | C10: Mon | D10: 2 | E10: Nov 2026 | F10: E-commerce SEO Foundations + Black Friday / Cyber Monday SEO | G10: Educate | H10: SLIDE | I10: LinkedIn Slide Post (PDF carousel) | J10: Instagram Slide Post (carousel) | K10: Product vs category page intent: which page should rank for what | L10: Your product page is ranking for the wrong search. Here's why. | M10: category page vs product page SEO | N10: search intent ecommerce, collection page SEO, product page SEO, keyword mapping for ecommerce | O10: "Why is my product page ranking for a broad search and not converting?" Because it's the wrong page for that search. Google reads intent first. → "running shoes" = I want to compare options → category page → "nike pegasus 41 mens size 10" = I know what I want → product page → "best running shoes for flat feet" = I want advice → guide that links to a category → "running shoes black friday" = I want deals → seasonal collection When you force a product page onto a broad search, two things happen. It struggles to rank. And when it does, people bounce because they wanted choice. The fix is a simple keyword map: one search intent, one page type, one URL. The carousel walks through how to build it for your store. Comment "INTENTMAP" and I'll send you the E-commerce Keyword-to-Page Intent Map. #EcommerceSEO #SearchIntent #ShopifySEO #KeywordResearch | P10: #EcommerceSEO #SearchIntent #ShopifySEO #KeywordResearch | Q10: Product page or category page? Google decides by intent. → "running shoes" = category → "pegasus 41 size 10" = product → "best shoes for flat feet" = guide → "running shoes black friday" = seasonal collection One intent. One page type. One URL. Save this before you write your next title tag. Comment "INTENTMAP" for the E-commerce Keyword-to-Page Intent Map. #searchintent #ecommerceseo #keywordresearch #shopifyseo #seotips #onlinestore #productpage #woocommerce #ecommercetips #seostrategy #shopifystore #contentstrategy | R10: #searchintent #ecommerceseo #keywordresearch #shopifyseo #seotips #onlinestore #productpage #woocommerce #ecommercetips #seostrategy #shopifystore #contentstrategy | S10: Slide 1: Your product page is ranking for the wrong search. | Product vs category page intent, explained. Slide 2: Google reads intent first | Before your title, your copy or your links. What does the searcher want to do next? Slide 3: Broad search = compare | "running shoes" → category page. People want choice, filters, prices. Slide 4: Specific search = buy | "nike pegasus 41 mens size 10" → product page. They know exactly what they want. Slide 5: Question search = learn | "best running shoes for flat feet" → guide or buying page that links to the category. Slide 6: Seasonal search = deals | "running shoes black friday" → seasonal collection on a permanent URL. Slide 7: What goes wrong | A product page forced onto a broad search ranks poorly and converts worse. Slide 8: Build the map | Column 1: keyword. Column 2: intent. Column 3: page type. Column 4: URL. One URL per intent. Slide 9: Check it in Search Console | Performance → Pages → pick a product → Queries. Broad queries here = a missing category page. Slide 10: Comment "INTENTMAP" | Get the E-commerce Keyword-to-Page Intent Map. Follow Mehrooz for more store SEO. | T10: Design a 10-slide LinkedIn PDF carousel, 1080x1350 each. Clean premium editorial style: off-white #F4F7FD background, primary blue #1566D7 accents, navy #191A46 text, headlines in Bebas Neue (bold condensed, all caps), body in Inter; generous margins, faint grid lines, crisp vector icons, no stock-photo clutter. Cover slide like a premium guide cover: giant two-tone headline (key word in blue), small illustration/UI mockup, numbered contents list. Inner slides: big slide number in blue, Bebas Neue title, short Inter body, one diagram/mockup/checklist per slide. Last slide: navy CTA banner with download icon. SLIDE CONTENT: Slide 1: Your product page is ranking for the wrong search. | Product vs category page intent, explained. Slide 2: Google reads intent first | Before your title, your copy or your links. What does the searcher want to do next? Slide 3: Broad search = compare | "running shoes" → category page. People want choice, filters, prices. Slide 4: Specific search = buy | "nike pegasus 41 mens size 10" → product page. They know exactly what they want. Slide 5: Question search = learn | "best running shoes for flat feet" → guide or buying page that links to the category. Slide 6: Seasonal search = deals | "running shoes black friday" → seasonal collection on a permanent URL. Slide 7: What goes wrong | A product page forced onto a broad search ranks poorly and converts worse. Slide 8: Build the map | Column 1: keyword. Column 2: intent. Column 3: page type. Column 4: URL. One URL per intent. Slide 9: Check it in Search Console | Performance → Pages → pick a product → Queries. Broad queries here = a missing category page. Slide 10: Comment "INTENTMAP" | Get the E-commerce Keyword-to-Page Intent Map. Follow Mehrooz for more store SEO. Footer on every frame: small circular headshot avatar + name tag 'Muhammad Mehrooz Shafique · Co-Founder, Permanent SEO' bottom-left; Permanent SEO 'P' logo (rising bar-chart + arrow mark) bottom-right. All text spelled exactly as written, sharp and legible on mobile; no extra words, no watermarks. | U10: Design a 10-slide Instagram carousel, 1080x1350 each. Bold creator style: deep gradient background #345DF5 (top) to #191A46 (bottom), huge white Bebas Neue / Anton condensed headline, key words highlighted in #1566D7 highlight boxes or light-blue text, high contrast. Slide 1 = scroll-stopping cover with giant condensed headline and a 'swipe →' cue; inner slides alternate navy and white backgrounds, big blue slide number, max 25 words, one icon or mini-diagram each; last slide = CTA with comment keyword in a blue pill. SLIDE CONTENT: Slide 1: Your product page is ranking for the wrong search. | Product vs category page intent, explained. Slide 2: Google reads intent first | Before your title, your copy or your links. What does the searcher want to do next? Slide 3: Broad search = compare | "running shoes" → category page. People want choice, filters, prices. Slide 4: Specific search = buy | "nike pegasus 41 mens size 10" → product page. They know exactly what they want. Slide 5: Question search = learn | "best running shoes for flat feet" → guide or buying page that links to the category. Slide 6: Seasonal search = deals | "running shoes black friday" → seasonal collection on a permanent URL. Slide 7: What goes wrong | A product page forced onto a broad search ranks poorly and converts worse. Slide 8: Build the map | Column 1: keyword. Column 2: intent. Column 3: page type. Column 4: URL. One URL per intent. Slide 9: Check it in Search Console | Performance → Pages → pick a product → Queries. Broad queries here = a missing category page. Slide 10: Comment "INTENTMAP" | Get the E-commerce Keyword-to-Page Intent Map. Follow Mehrooz for more store SEO. Footer on every frame: small circular headshot avatar + name tag 'Muhammad Mehrooz Shafique · Co-Founder, Permanent SEO' bottom-left; Permanent SEO 'P' logo (rising bar-chart + arrow mark) bottom-right. All text spelled exactly as written, sharp and legible on mobile; no extra words, no watermarks. | V10: INTENTMAP | W10: E-commerce Keyword-to-Page Intent Map (Google Sheet template with examples) | X10: Your product page might be ranking for the wrong search. Google reads intent before anything else. Here's how to match search type to page type in an online store. --- Broad search = compare. "running shoes" → category page. People want choice, filters and prices. --- Specific search = buy. "nike pegasus 41 mens size 10" → product page. --- Question search = learn. "best running shoes for flat feet" → guide that links into the category. Seasonal search = deals. "running shoes black friday" → seasonal collection on a permanent URL. --- Quick check: Search Console → Performance → Pages → open a product → Queries. Broad queries landing on a product page usually means a missing category page. --- Build a 4-column map: keyword, intent, page type, URL. One intent. One page. One URL. #EcommerceSEO | Y10: Repost the Instagram caption + same visual | Z10: X thread · Facebook carousel · Reddit text post | AD10: r/shopify | AE10: How to decide if a keyword should go to a product page or a collection page | AF10: A common issue I see in Shopify stores: product pages ranking (badly) for broad searches that should go to a collection. A simple way to decide is to look at what the searcher wants to do next. - Broad terms like "running shoes" usually mean they want to compare. Collection page. - Specific terms with model, size or colour mean they know what they want. Product page. - Questions like "best X for Y" mean they want advice. A guide or buying page that links to the collection. - Seasonal terms like "X black friday" mean they want deals. A seasonal collection that lives on the same URL every year. Fastest way to check your own store: Search Console, Performance, Pages, click a product URL, then switch to Queries. If you see broad category-style queries there, you probably need a stronger collection page for them. Once you know, map it in a sheet: keyword, intent, page type, URL. One intent per URL. How do you all handle this when a product is basically the whole category, like a single-product store? | AG10: 08:30 / 12:30 | AH10: Planned
